Workbook

Sheet README
A1: Travel Itineraries — Relational Workbook
A3: How the sheets connect (same structure as the database tables)
A4: Itineraries (1 row per itinerary) PRIMARY KEY: itinerary_id
A5: Themes (1 row per itinerary) itinerary_id → Itineraries
A6: Days (1 row per day) itinerary_id → Itineraries, key = itinerary_id + day_number
A7: Locations (1 row per unique place) PRIMARY KEY: location_id
A8: Day_Locations (stops of each day, ordered) itinerary_id + day_number → Days, location_id → Locations
A9: Tags (1 row per unique tag) PRIMARY KEY: tag_id, category = occasion / travel_style / culture / season / trip_type
A10: Itinerary_Tags (which tags an itinerary has) itinerary_id → Itineraries, tag_id → Tags
A12: Colour legend
A13: Dark blue header = data you type / paste.
A14: Grey-blue header + shaded cells = formulas (auto-calculated; do not overwrite).
... A41: Frontend filter controls and runtime filtering are implemented in the Next.js source code, not in this workbook. Verify the frontend Direction filter separately.

Sheet Filter_Options
A1: category_no | B1: category_name | C1: option_no | D1: option_label | E1: rule_type | F1: rule_text | G1: min | H1: max | I1: tag_id_1 | J1: tag_id_2 | K1: tag_id_3 | L1: option_code | M1: itineraries_matching | N1: tags_used (auto)
A2: 1 | B2: Direction | C2: 1 | D2: North | E2: direction | F2: north | L2: =A2&"."&C2 | M2: =SUM(INDEX(Filter_Matrix!$C$2:$AL$100,0,ROW()-1)) | N2: =IF(I2="","",IFERROR(INDEX(Tags!$C:$C,MATCH(I2,Tags!$A:$A,0)),"?")&IF(J2="","",", "&IFERROR(INDEX(Tags!$C:$C,MATCH(J2,Tags!$A:$A,0)),"?"))&IF(K2="","",", "&IFERROR(INDEX(Tags!$C:$C,MATCH(K2,Tags!$A:$A,0)),"?")))
A3: 1 | B3: Direction | C3: 2 | D3: South | E3: direction | F3: south | L3: =A3&"."&C3 | M3: =SUM(INDEX(Filter_Matrix!$C$2:$AL$100,0,ROW()-1)) | N3: =IF(I3="","",IFERROR(INDEX(Tags!$C:$C,MATCH(I3,Tags!$A:$A,0)),"?")&IF(J3="","",", "&IFERROR(INDEX(Tags!$C:$C,MATCH(J3,Tags!$A:$A,0)),"?"))&IF(K3="","",", "&IFERROR(INDEX(Tags!$C:$C,MATCH(K3,Tags!$A:$A,0)),"?")))
A4: 1 | B4: Direction | C4: 3 | D4: East | E4: direction | F4: east | L4: =A4&"."&C4 | M4: =SUM(INDEX(Filter_Matrix!$C$2:$AL$100,0,ROW()-1)) | N4: =IF(I4="","",IFERROR(INDEX(Tags!$C:$C,MATCH(I4,Tags!$A:$A,0)),"?")&IF(J4="","",", "&IFERROR(INDEX(Tags!$C:$C,MATCH(J4,Tags!$A:$A,0)),"?"))&IF(K4="","",", "&IFERROR(INDEX(Tags!$C:$C,MATCH(K4,Tags!$A:$A,0)),"?")))
A5: 1 | B5: Direction | C5: 4 | D5: West | E5: direction | F5: west | L5: =A5&"."&C5 | M5: =SUM(INDEX(Filter_Matrix!$C$2:$AL$100,0,ROW()-1)) | N5: =IF(I5="","",IFERROR(INDEX(Tags!$C:$C,MATCH(I5,Tags!$A:$A,0)),"?")&IF(J5="","",", "&IFERROR(INDEX(Tags!$C:$C,MATCH(J5,Tags!$A:$A,0)),"?"))&IF(K5="","",", "&IFERROR(INDEX(Tags!$C:$C,MATCH(K5,Tags!$A:$A,0)),"?")))
A6: 1 | B6: Direction | C6: 5 | D6: Northeast | E6: direction | F6: northeast | L6: =A6&"."&C6 | M6: =SUM(INDEX(Filter_Matrix!$C$2:$AL$100,0,ROW()-1)) | N6: =IF(I6="","",IFERROR(INDEX(Tags!$C:$C,MATCH(I6,Tags!$A:$A,0)),"?")&IF(J6="","",", "&IFERROR(INDEX(Tags!$C:$C,MATCH(J6,Tags!$A:$A,0)),"?"))&IF(K6="","",", "&IFERROR(INDEX(Tags!$C:$C,MATCH(K6,Tags!$A:$A,0)),"?")))
A7: 1 | B7: Direction | C7: 6 | D7: Central | E7: direction | F7: central | L7: =A7&"."&C7 | M7: =SUM(INDEX(Filter_Matrix!$C$2:$AL$100,0,ROW()-1)) | N7: =IF(I7="","",IFERROR(INDEX(Tags!$C:$C,MATCH(I7,Tags!$A:$A,0)),"?")&IF(J7="","",", "&IFERROR(INDEX(Tags!$C:$C,MATCH(J7,Tags!$A:$A,0)),"?"))&IF(K7="","",", "&IFERROR(INDEX(Tags!$C:$C,MATCH(K7,Tags!$A:$A,0)),"?")))
A8: 2 | B8: Budget (INR) | C8: 1 | D8: Under 5,000 | E8: range_overlap | G8: 0 | H8: 4999 | L8: =A8&"."&C8 | M8: =SUM(INDEX(Filter_Matrix!$C$2:$AL$100,0,ROW()-1)) | N8: =IF(I8="","",IFERROR(INDEX(Tags!$C:$C,MATCH(I8,Tags!$A:$A,0)),"?")&IF(J8="","",", "&IFERROR(INDEX(Tags!$C:$C,MATCH(J8,Tags!$A:$A,0)),"?"))&IF(K8="","",", "&IFERROR(INDEX(Tags!$C:$C,MATCH(K8,Tags!$A:$A,0)),"?")))
A9: 2 | B9: Budget (INR) | C9: 2 | D9: 5,000 – 7,999 | E9: range_overlap | G9: 5000 | H9: 7999 | L9: =A9&"."&C9 | M9: =SUM(INDEX(Filter_Matrix!$C$2:$AL$100,0,ROW()-1)) | N9: =IF(I9="","",IFERROR(INDEX(Tags!$C:$C,MATCH(I9,Tags!$A:$A,0)),"?")&IF(J9="","",", "&IFERROR(INDEX(Tags!$C:$C,MATCH(J9,Tags!$A:$A,0)),"?"))&IF(K9="","",", "&IFERROR(INDEX(Tags!$C:$C,MATCH(K9,Tags!$A:$A,0)),"?")))
A10: 2 | B10: Budget (INR) | C10: 3 | D10: 8,000 – 11,999 | E10: range_overlap | G10: 8000 | H10: 11999 | L10: =A10&"."&C10 | M10: =SUM(INDEX(Filter_Matrix!$C$2:$AL$100,0,ROW()-1)) | N10: =IF(I10="","",IFERROR(INDEX(Tags!$C:$C,MATCH(I10,Tags!$A:$A,0)),"?")&IF(J10="","",", "&IFERROR(INDEX(Tags!$C:$C,MATCH(J10,Tags!$A:$A,0)),"?"))&IF(K10="","",", "&IFERROR(INDEX(Tags!$C:$C,MATCH(K10,Tags!$A:$A,0)),"?")))
A11: 2 | B11: Budget (INR) | C11: 4 | D11: 12,000 – 17,999 | E11: range_overlap | G11: 12000 | H11: 17999 | L11: =A11&"."&C11 | M11: =SUM(INDEX(Filter_Matrix!$C$2:$AL$100,0,ROW()-1)) | N11: =IF(I11="","",IFERROR(INDEX(Tags!$C:$C,MATCH(I11,Tags!$A:$A,0)),"?")&IF(J11="","",", "&IFERROR(INDEX(Tags!$C:$C,MATCH(J11,Tags!$A:$A,0)),"?"))&IF(K11="","",", "&IFERROR(INDEX(Tags!$C:$C,MATCH(K11,Tags!$A:$A,0)),"?")))
A12: 2 | B12: Budget (INR) | C12: 5 | D12: 18,000 – 24,999 | E12: range_overlap | G12: 18000 | H12: 24999 | L12: =A12&"."&C12 | M12: =SUM(INDEX(Filter_Matrix!$C$2:$AL$100,0,ROW()-1)) | N12: =IF(I12="","",IFERROR(INDEX(Tags!$C:$C,MATCH(I12,Tags!$A:$A,0)),"?")&IF(J12="","",", "&IFERROR(INDEX(Tags!$C:$C,MATCH(J12,Tags!$A:$A,0)),"?"))&IF(K12="","",", "&IFERROR(INDEX(Tags!$C:$C,MATCH(K12,Tags!$A:$A,0)),"?")))
A13: 2 | B13: Budget (INR) | C13: 6 | D13: 25,000 and above | E13: range_overlap | G13: 25000 | H13: 999999 | L13: =A13&"."&C13 | M13: =SUM(INDEX(Filter_Matrix!$C$2:$AL$100,0,ROW()-1)) | N13: =IF(I13="","",IFERROR(INDEX(Tags!$C:$C,MATCH(I13,Tags!$A:$A,0)),"?")&IF(J13="","",", "&IFERROR(INDEX(Tags!$C:$C,MATCH(J13,Tags!$A:$A,0)),"?"))&IF(K13="","",", "&IFERROR(INDEX(Tags!$C:$C,MATCH(K13,Tags!$A:$A,0)),"?")))
A14: 3 | B14: Available Time (days) | C14: 1 | D14: 1–2 days | E14: range_in | G14: 1 | H14: 2 | L14: =A14&"."&C14 | M14: =SUM(INDEX(Filter_Matrix!$C$2:$AL$100,0,ROW()-1)) | N14: =IF(I14="","",IFERROR(INDEX(Tags!$C:$C,MATCH(I14,Tags!$A:$A,0)),"?")&IF(J14="","",", "&IFERROR(INDEX(Tags!$C:$C,MATCH(J14,Tags!$A:$A,0)),"?"))&IF(K14="","",", "&IFERROR(INDEX(Tags!$C:$C,MATCH(K14,Tags!$A:$A,0)),"?")))
A15: 3 | B15: Available Time (days) | C15: 2 | D15: 3 days | E15: range_in | G15: 3 | H15: 3 | L15: =A15&"."&C15 | M15: =SUM(INDEX(Filter_Matrix!$C$2:$AL$100,0,ROW()-1)) | N15: =IF(I15="","",IFERROR(INDEX(Tags!$C:$C,MATCH(I15,Tags!$A:$A,0)),"?")&IF(J15="","",", "&IFERROR(INDEX(Tags!$C:$C,MATCH(J15,Tags!$A:$A,0)),"?"))&IF(K15="","",", "&IFERROR(INDEX(Tags!$C:$C,MATCH(K15,Tags!$A:$A,0)),"?")))
A16: 3 | B16: Available Time (days) | C16: 3 | D16: 4 days | E16: range_in | G16: 4 | H16: 4 | L16: =A16&"."&C16 | M16: =SUM(INDEX(Filter_Matrix!$C$2:$AL$100,0,ROW()-1)) | N16: =IF(I16="","",IFERROR(INDEX(Tags!$C:$C,MATCH(I16,Tags!$A:$A,0)),"?")&IF(J16="","",", "&IFERROR(INDEX(Tags!$C:$C,MATCH(J16,Tags!$A:$A,0)),"?"))&IF(K16="","",", "&IFERROR(INDEX(Tags!$C:$C,MATCH(K16,Tags!$A:$A,0)),"?")))
A17: 3 | B17: Available Time (days) | C17: 4 | D17: 5 days | E17: range_in | G17: 5 | H17: 5 | L17: =A17&"."&C17 | M17: =SUM(INDEX(Filter_Matrix!$C$2:$AL$100,0,ROW()-1)) | N17: =IF(I17="","",IFERROR(INDEX(Tags!$C:$C,MATCH(I17,Tags!$A:$A,0)),"?")&IF(J17="","",", "&IFERROR(INDEX(Tags!$C:$C,MATCH(J17,Tags!$A:$A,0)),"?"))&IF(K17="","",", "&IFERROR(INDEX(Tags!$C:$C,MATCH(K17,Tags!$A:$A,0)),"?")))
A18: 3 | B18: Available Time (days) | C18: 5 | D18: 6–7 days | E18: range_in | G18: 6 | H18: 7 | L18: =A18&"."&C18 | M18: =SUM(INDEX(Filter_Matrix!$C$2:$AL$100,0,ROW()-1)) | N18: =IF(I18="","",IFERROR(INDEX(Tags!$C:$C,MATCH(I18,Tags!$A:$A,0)),"?")&IF(J18="","",", "&IFERROR(INDEX(Tags!$C:$C,MATCH(J18,Tags!$A:$A,0)),"?"))&IF(K18="","",", "&IFERROR(INDEX(Tags!$C:$C,MATCH(K18,Tags!$A:$A,0)),"?")))
A19: 3 | B19: Available Time (days) | C19: 6 | D19: 8+ days | E19: range_in | G19: 8 | H19: 99 | L19: =A19&"."&C19 | M19: =SUM(INDEX(Filter_Matrix!$C$2:$AL$100,0,ROW()-1)) | N19: =IF(I19="","",IFERROR(INDEX(Tags!$C:$C,MATCH(I19,Tags!$A:$A,0)),"?")&IF(J19="","",", "&IFERROR(INDEX(Tags!$C:$C,MATCH(J19,Tags!$A:$A,0)),"?"))&IF(K19="","",", "&IFERROR(INDEX(Tags!$C:$C,MATCH(K19,Tags!$A:$A,0)),"?")))
A20: 4 | B20: Occasion | C20: 1 | D20: Weekend | E20: tag | I20: 15 | L20: =A20&"."&C20 | M20: =SUM(INDEX(Filter_Matrix!$C$2:$AL$100,0,ROW()-1)) | N20: =IF(I20="","",IFERROR(INDEX(Tags!$C:$C,MATCH(I20,Tags!$A:$A,0)),"?")&IF(J20="","",", "&IFERROR(INDEX(Tags!$C:$C,MATCH(J20,Tags!$A:$A,0)),"?"))&IF(K20="","",", "&IFERROR(INDEX(Tags!$C:$C,MATCH(K20,Tags!$A:$A,0)),"?")))
A21: 4 | B21: Occasion | C21: 2 | D21: Long weekend | E21: tag | I21: 1 | L21: =A21&"."&C21 | M21: =SUM(INDEX(Filter_Matrix!$C$2:$AL$100,0,ROW()-1)) | N21: =IF(I21="","",IFERROR(INDEX(Tags!$C:$C,MATCH(I21,Tags!$A:$A,0)),"?")&IF(J21="","",", "&IFERROR(INDEX(Tags!$C:$C,MATCH(J21,Tags!$A:$A,0)),"?"))&IF(K21="","",", "&IFERROR(INDEX(Tags!$C:$C,MATCH(K21,Tags!$A:$A,0)),"?")))
A22: 4 | B22: Occasion | C22: 3 | D22: Spontaneous | E22: tag | I22: 18 | L22: =A22&"."&C22 | M22: =SUM(INDEX(Filter_Matrix!$C$2:$AL$100,0,ROW()-1)) | N22: =IF(I22="","",IFERROR(INDEX(Tags!$C:$C,MATCH(I22,Tags!$A:$A,0)),"?")&IF(J22="","",", "&IFERROR(INDEX(Tags!$C:$C,MATCH(J22,Tags!$A:$A,0)),"?"))&IF(K22="","",", "&IFERROR(INDEX(Tags!$C:$C,MATCH(K22,Tags!$A:$A,0)),"?")))
A23: 4 | B23: Occasion | C23: 4 | D23: Festive | E23: tag | I23: 58 | J23: 48 | L23: =A23&"."&C23 | M23: =SUM(INDEX(Filter_Matrix!$C$2:$AL$100,0,ROW()-1)) | N23: =IF(I23="","",IFERROR(INDEX(Tags!$C:$C,MATCH(I23,Tags!$A:$A,0)),"?")&IF(J23="","",", "&IFERROR(INDEX(Tags!$C:$C,MATCH(J23,Tags!$A:$A,0)),"?"))&IF(K23="","",", "&IFERROR(INDEX(Tags!$C:$C,MATCH(K23,Tags!$A:$A,0)),"?")))
A24: 4 | B24: Occasion | C24: 5 | D24: Solo | E24: tag | I24: 32 | L24: =A24&"."&C24 | M24: =SUM(INDEX(Filter_Matrix!$C$2:$AL$100,0,ROW()-1)) | N24: =IF(I24="","",IFERROR(INDEX(Tags!$C:$C,MATCH(I24,Tags!$A:$A,0)),"?")&IF(J24="","",", "&IFERROR(INDEX(Tags!$C:$C,MATCH(J24,Tags!$A:$A,0)),"?"))&IF(K24="","",", "&IFERROR(INDEX(Tags!$C:$C,MATCH(K24,Tags!$A:$A,0)),"?")))
A25: 4 | B25: Occasion | C25: 6 | D25: Friends, couple & family | E25: tag | I25: 33 | J25: 34 | K25: 35 | L25: =A25&"."&C25 | M25: =SUM(INDEX(Filter_Matrix!$C$2:$AL$100,0,ROW()-1)) | N25: =IF(I25="","",IFERROR(INDEX(Tags!$C:$C,MATCH(I25,Tags!$A:$A,0)),"?")&IF(J25="","",", "&IFERROR(INDEX(Tags!$C:$C,MATCH(J25,Tags!$A:$A,0)),"?"))&IF(K25="","",", "&IFERROR(INDEX(Tags!$C:$C,MATCH(K25,Tags!$A:$A,0)),"?")))
A26: 5 | B26: Culture | C26: 1 | D26: Heritage | E26: tag | I26: 6 | L26: =A26&"."&C26 | M26: =SUM(INDEX(Filter_Matrix!$C$2:$AL$100,0,ROW()-1)) | N26: =IF(I26="","",IFERROR(INDEX(Tags!$C:$C,MATCH(I26,Tags!$A:$A,0)),"?")&IF(J26="","",", "&IFERROR(INDEX(Tags!$C:$C,MATCH(J26,Tags!$A:$A,0)),"?"))&IF(K26="","",", "&IFERROR(INDEX(Tags!$C:$C,MATCH(K26,Tags!$A:$A,0)),"?")))
A27: 5 | B27: Culture | C27: 2 | D27: Local food | E27: tag | I27: 7 | L27: =A27&"."&C27 | M27: =SUM(INDEX(Filter_Matrix!$C$2:$AL$100,0,ROW()-1)) | N27: =IF(I27="","",IFERROR(INDEX(Tags!$C:$C,MATCH(I27,Tags!$A:$A,0)),"?")&IF(J27="","",", "&IFERROR(INDEX(Tags!$C:$C,MATCH(J27,Tags!$A:$A,0)),"?"))&IF(K27="","",", "&IFERROR(INDEX(Tags!$C:$C,MATCH(K27,Tags!$A:$A,0)),"?")))
A28: 5 | B28: Culture | C28: 3 | D28: Folk art & crafts | E28: tag | I28: 8 | J28: 9 | L28: =A28&"."&C28 | M28: =SUM(INDEX(Filter_Matrix!$C$2:$AL$100,0,ROW()-1)) | N28: =IF(I28="","",IFERROR(INDEX(Tags!$C:$C,MATCH(I28,Tags!$A:$A,0)),"?")&IF(J28="","",", "&IFERROR(INDEX(Tags!$C:$C,MATCH(J28,Tags!$A:$A,0)),"?"))&IF(K28="","",", "&IFERROR(INDEX(Tags!$C:$C,MATCH(K28,Tags!$A:$A,0)),"?")))
A29: 5 | B29: Culture | C29: 4 | D29: Villages | E29: tag | I29: 21 | L29: =A29&"."&C29 | M29: =SUM(INDEX(Filter_Matrix!$C$2:$AL$100,0,ROW()-1)) | N29: =IF(I29="","",IFERROR(INDEX(Tags!$C:$C,MATCH(I29,Tags!$A:$A,0)),"?")&IF(J29="","",", "&IFERROR(INDEX(Tags!$C:$C,MATCH(J29,Tags!$A:$A,0)),"?"))&IF(K29="","",", "&IFERROR(INDEX(Tags!$C:$C,MATCH(K29,Tags!$A:$A,0)),"?")))
A30: 5 | B30: Culture | C30: 5 | D30: Festivals | E30: tag | I30: 41 | J30: 49 | L30: =A30&"."&C30 | M30: =SUM(INDEX(Filter_Matrix!$C$2:$AL$100,0,ROW()-1)) | N30: =IF(I30="","",IFERROR(INDEX(Tags!$C:$C,MATCH(I30,Tags!$A:$A,0)),"?")&IF(J30="","",", "&IFERROR(INDEX(Tags!$C:$C,MATCH(J30,Tags!$A:$A,0)),"?"))&IF(K30="","",", "&IFERROR(INDEX(Tags!$C:$C,MATCH(K30,Tags!$A:$A,0)),"?")))
A31: 5 | B31: Culture | C31: 6 | D31: Local culture | E31: tag | I31: 50 | L31: =A31&"."&C31 | M31: =SUM(INDEX(Filter_Matrix!$C$2:$AL$100,0,ROW()-1)) | N31: =IF(I31="","",IFERROR(INDEX(Tags!$C:$C,MATCH(I31,Tags!$A:$A,0)),"?")&IF(J31="","",", "&IFERROR(INDEX(Tags!$C:$C,MATCH(J31,Tags!$A:$A,0)),"?"))&IF(K31="","",", "&IFERROR(INDEX(Tags!$C:$C,MATCH(K31,Tags!$A:$A,0)),"?")))
A32: 6 | B32: Weather & Season | C32: 1 | D32: Winter | E32: tag | I32: 10 | L32: =A32&"."&C32 | M32: =SUM(INDEX(Filter_Matrix!$C$2:$AL$100,0,ROW()-1)) | N32: =IF(I32="","",IFERROR(INDEX(Tags!$C:$C,MATCH(I32,Tags!$A:$A,0)),"?")&IF(J32="","",", "&IFERROR(INDEX(Tags!$C:$C,MATCH(J32,Tags!$A:$A,0)),"?"))&IF(K32="","",", "&IFERROR(INDEX(Tags!$C:$C,MATCH(K32,Tags!$A:$A,0)),"?")))
A33: 6 | B33: Weather & Season | C33: 2 | D33: Summer | E33: tag | I33: 27 | L33: =A33&"."&C33 | M33: =SUM(INDEX(Filter_Matrix!$C$2:$AL$100,0,ROW()-1)) | N33: =IF(I33="","",IFERROR(INDEX(Tags!$C:$C,MATCH(I33,Tags!$A:$A,0)),"?")&IF(J33="","",", "&IFERROR(INDEX(Tags!$C:$C,MATCH(J33,Tags!$A:$A,0)),"?"))&IF(K33="","",", "&IFERROR(INDEX(Tags!$C:$C,MATCH(K33,Tags!$A:$A,0)),"?")))
A34: 6 | B34: Weather & Season | C34: 3 | D34: Monsoon & waterfalls | E34: tag | I34: 29 | J34: 36 | L34: =A34&"."&C34 | M34: =SUM(INDEX(Filter_Matrix!$C$2:$AL$100,0,ROW()-1)) | N34: =IF(I34="","",IFERROR(INDEX(Tags!$C:$C,MATCH(I34,Tags!$A:$A,0)),"?")&IF(J34="","",", "&IFERROR(INDEX(Tags!$C:$C,MATCH(J34,Tags!$A:$A,0)),"?"))&IF(K34="","",", "&IFERROR(INDEX(Tags!$C:$C,MATCH(K34,Tags!$A:$A,0)),"?")))
A35: 6 | B35: Weather & Season | C35: 4 | D35: Autumn | E35: tag | I35: 22 | L35: =A35&"."&C35 | M35: =SUM(INDEX(Filter_Matrix!$C$2:$AL$100,0,ROW()-1)) | N35: =IF(I35="","",IFERROR(INDEX(Tags!$C:$C,MATCH(I35,Tags!$A:$A,0)),"?")&IF(J35="","",", "&IFERROR(INDEX(Tags!$C:$C,MATCH(J35,Tags!$A:$A,0)),"?"))&IF(K35="","",", "&IFERROR(INDEX(Tags!$C:$C,MATCH(K35,Tags!$A:$A,0)),"?")))
A36: 6 | B36: Weather & Season | C36: 5 | D36: Spring | E36: tag | I36: 57 | L36: =A36&"."&C36 | M36: =SUM(INDEX(Filter_Matrix!$C$2:$AL$100,0,ROW()-1)) | N36: =IF(I36="","",IFERROR(INDEX(Tags!$C:$C,MATCH(I36,Tags!$A:$A,0)),"?")&IF(J36="","",", "&IFERROR(INDEX(Tags!$C:$C,MATCH(J36,Tags!$A:$A,0)),"?"))&IF(K36="","",", "&IFERROR(INDEX(Tags!$C:$C,MATCH(K36,Tags!$A:$A,0)),"?")))
A37: 6 | B37: Weather & Season | C37: 6 | D37: Pleasant | E37: tag | I37: 11 | L37: =A37&"."&C37 | M37: =SUM(INDEX(Filter_Matrix!$C$2:$AL$100,0,ROW()-1)) | N37: =IF(I37="","",IFERROR(INDEX(Tags!$C:$C,MATCH(I37,Tags!$A:$A,0)),"?")&IF(J37="","",", "&IFERROR(INDEX(Tags!$C:$C,MATCH(J37,Tags!$A:$A,0)),"?"))&IF(K37="","",", "&IFERROR(INDEX(Tags!$C:$C,MATCH(K37,Tags!$A:$A,0)),"?")))

Sheet Filter_Matrix
A1: itinerary_id | B1: title | C1: =Filter_Options!$L$2 | D1: =Filter_Options!$L$3 | E1: =Filter_Options!$L$4 | F1: =Filter_Options!$L$5 | G1: =Filter_Options!$L$6 | H1: =Filter_Options!$L$7 | I1: =Filter_Options!$L$8 | J1: =Filter_Options!$L$9 | K1: =Filter_Options!$L$10 | L1: =Filter_Options!$L$11 | M1: =Filter_Options!$L$12 | N1: =Filter_Options!$L$13 | O1: =Filter_Options!$L$14 | P1: =Filter_Options!$L$15 | Q1: =Filter_Options!$L$16 | R1: =Filter_Options!$L$17 | S1: =Filter_Options!$L$18 | T1: =Filter_Options!$L$19 | U1: =Filter_Options!$L$20 | V1: =Filter_Options!$L$21 | W1: =Filter_Options!$L$22 | X1: =Filter_Options!$L$23 | Y1: =Filter_Options!$L$24 | Z1: =Filter_Options!$L$25 | AA1: =Filter_Options!$L$26 | AB1: =Filter_Options!$L$27 | AC1: =Filter_Options!$L$28 | AD1: =Filter_Options!$L$29 | AE1: =Filter_Options!$L$30 | AF1: =Filter_Options!$L$31 | AG1: =Filter_Options!$L$32 | AH1: =Filter_Options!$L$33 | AI1: =Filter_Options!$L$34 | AJ1: =Filter_Options!$L$35 | AK1: =Filter_Options!$L$36 | AL1: =Filter_Options!$L$37
A2: =IF(Itineraries!A2="","",Itineraries!A2) | B2: =IF(Itineraries!A2="","",Itineraries!C2) | C2: =IF($A2="","",--(Itineraries!$J2=Filter_Options!$F$2)) | D2: =IF($A2="","",--(Itineraries!$J2=Filter_Options!$F$3)) | E2: =IF($A2="","",--(Itineraries!$J2=Filter_Options!$F$4)) | F2: =IF($A2="","",--(Itineraries!$J2=Filter_Options!$F$5)) | G2: =IF($A2="","",--(Itineraries!$J2=Filter_Options!$F$6)) | H2: =IF($A2="","",--(Itineraries!$J2=Filter_Options!$F$7)) | I2: =IF($A2="","",--AND(Itineraries!$K2<=Filter_Options!$H$8,Itineraries!$L2>=Filter_Options!$G$8)) | J2: =IF($A2="","",--AND(Itineraries!$K2<=Filter_Options!$H$9,Itineraries!$L2>=Filter_Options!$G$9)) | K2: =IF($A2="","",--AND(Itineraries!$K2<=Filter_Options!$H$10,Itineraries!$L2>=Filter_Options!$G$10)) | L2: =IF($A2="","",--AND(Itineraries!$K2<=Filter_Options!$H$11,Itineraries!$L2>=Filter_Options!$G$11)) | M2: =IF($A2="","",--AND(Itineraries!$K2<=Filter_Options!$H$12,Itineraries!$L2>=Filter_Options!$G$12)) | N2: =IF($A2="","",--AND(Itineraries!$K2<=Filter_Options!$H$13,Itineraries!$L2>=Filter_Options!$G$13)) | O2: =IF($A2="","",--AND(Itineraries!$E2>=Filter_Options!$G$14,Itineraries!$E2<=Filter_Options!$H$14)) | P2: =IF($A2="","",--AND(Itineraries!$E2>=Filter_Options!$G$15,Itineraries!$E2<=Filter_Options!$H$15)) | Q2: =IF($A2="","",--AND(Itineraries!$E2>=Filter_Options!$G$16,Itineraries!$E2<=Filter_Options!$H$16)) | R2: =IF($A2="","",--AND(Itineraries!$E2>=Filter_Options!$G$17,Itineraries!$E2<=Filter_Options!$H$17)) | S2: =IF($A2="","",--AND(Itineraries!$E2>=Filter_Options!$G$18,Itineraries!$E2<=Filter_Options!$H$18)) | T2: =IF($A2="","",--AND(Itineraries!$E2>=Filter_Options!$G$19,Itineraries!$E2<=Filter_Options!$H$19)) | U2: =IF($A2="","",--((IF(Filter_Options!$I$20="",0,COUNTIFS(Itinerary_Tags!$A:$A,$A2,Itinerary_Tags!$B:$B,Filter_Options!$I$20))+IF(Filter_Options!$J$20="",0,COUNTIFS(Itinerary_Tags!$A:$A,$A2,Itinerary_Tags!$B:$B,Filter_Options!$J$20))+IF(Filter_Options!$K$20="",0,COUNTIFS(Itinerary_Tags!$A:$A,$A2,Itinerary_Tags!$B:$B,Filter_Options!$K$20)))>0)) | V2: =IF($A2="","",--((IF(Filter_Options!$I$21="",0,COUNTIFS(Itinerary_Tags!$A:$A,$A2,Itinerary_Tags!$B:$B,Filter_Options!$I$21))+IF(Filter_Options!$J$21="",0,COUNTIFS(Itinerary_Tags!$A:$A,$A2,Itinerary_Tags!$B:$B,Filter_Options!$J$21))+IF(Filter_Options!$K$21="",0,COUNTIFS(Itinerary_Tags!$A:$A,$A2,Itinerary_Tags!$B:$B,Filter_Options!$K$21)))>0)) | W2: =IF($A2="","",--((IF(Filter_Options!$I$22="",0,COUNTIFS(Itinerary_Tags!$A:$A,$A2,Itinerary_Tags!$B:$B,Filter_Options!$I$22))+IF(Filter_Options!$J$22="",0,COUNTIFS(Itinerary_Tags!$A:$A,$A2,Itinerary_Tags!$B:$B,Filter_Options!$J$22))+IF(Filter_Options!$K$22="",0,COUNTIFS(Itinerary_Tags!$A:$A,$A2,Itinerary_Tags!$B:$B,Filter_Options!$K$22)))>0)) | X2: =IF($A2="","",--((IF(Filter_Options!$I$23="",0,COUNTIFS(Itinerary_Tags!$A:$A,$A2,Itinerary_Tags!$B:$B,Filter_Options!$I$23))+IF(Filter_Options!$J$23="",0,COUNTIFS(Itinerary_Tags!$A:$A,$A2,Itinerary_Tags!$B:$B,Filter_Options!$J$23))+IF(Filter_Options!$K$23="",0,COUNTIFS(Itinerary_Tags!$A:$A,$A2,Itinerary_Tags!$B:$B,Filter_Options!$K$23)))>0)) | Y2: =IF($A2="","",--((IF(Filter_Options!$I$24="",0,COUNTIFS(Itinerary_Tags!$A:$A,$A2,Itinerary_Tags!$B:$B,Filter_Options!$I$24))+IF(Filter_Options!$J$24="",0,COUNTIFS(Itinerary_Tags!$A:$A,$A2,Itinerary_Tags!$B:$B,Filter_Options!$J$24))+IF(Filter_Options!$K$24="",0,COUNTIFS(Itinerary_Tags!$A:$A,$A2,Itinerary_Tags!$B:$B,Filter_Options!$K$24)))>0)) | Z2: =IF($A2="","",--((IF(Filter_Options!$I$25="",0,COUNTIFS(Itinerary_Tags!$A:$A,$A2,Itinerary_Tags!$B:$B,Filter_Options!$I$25))+IF(Filter_Options!$J$25="",0,COUNTIFS(Itinerary_Tags!$A:$A,$A2,Itinerary_Tags!$B:$B,Filter_Options!$J$25))+IF(Filter_Options!$K$25="",0,COUNTIFS(Itinerary_Tags!$A:$A,$A2,Itinerary_Tags!$B:$B,Filter_Options!$K$25)))>0)) | AA2: =IF($A2="","",--((IF(Filter_Options!$I$26="",0,COUNTIFS(Itinerary_Tags!$A:$A,$A2,Itinerary_Tags!$B:$B,Filter_Options!$I$26))+IF(Filter_Options!$J$26="",0,COUNTIFS(Itinerary_Tags!$A:$A,$A2,Itinerary_Tags!$B:$B,Filter_Options!$J$26))+IF(Filter_Options!$K$26="",0,COUNTIFS(Itinerary_Tags!$A:$A,$A2,Itinerary_Tags!$B:$B,Filter_Options!$K$26)))>0)) | AB2: =IF($A2="","",--((IF(Filter_Options!$I$27="",0,COUNTIFS(Itinerary_Tags!$A:$A,$A2,Itinerary_Tags!$B:$B,Filter_Options!$I$27))+IF(Filter_Options!$J$27="",0,COUNTIFS(Itinerary_Tags!$A:$A,$A2,Itinerary_Tags!$B:$B,Filter_Options!$J$27))+IF(Filter_Options!$K$27="",0,COUNTIFS(Itinerary_Tags!$A:$A,$A2,Itinerary_Tags!$B:$B,Filter_Options!$K$27)))>0)) | AC2: =IF($A2="","",--((IF(Filter_Options!$I$28="",0,COUNTIFS(Itinerary_Tags!$A:$A,$A2,Itinerary_Tags!$B:$B,Filter_Options!$I$28))+IF(Filter_Options!$J$28="",0,COUNTIFS(Itinerary_Tags!$A:$A,$A2,Itinerary_Tags!$B:$B,Filter_Options!$J$28))+IF(Filter_Options!$K$28="",0,COUNTIFS(Itinerary_Tags!$A:$A,$A2,Itinerary_Tags!$B:$B,Filter_Options!$K$28)))>0)) | AD2: =IF($A2="","",--((IF(Filter_Options!$I$29="",0,COUNTIFS(Itinerary_Tags!$A:$A,$A2,Itinerary_Tags!$B:$B,Filter_Options!$I$29))+IF(Filter_Options!$J$29="",0,COUNTIFS(Itinerary_Tags!$A:$A,$A2,Itinerary_Tags!$B:$B,Filter_Options!$J$29))+IF(Filter_Options!$K$29="",0,COUNTIFS(Itinerary_Tags!$A:$A,$A2,Itinerary_Tags!$B:$B,Filter_Options!$K$29)))>0)) | AE2: =IF($A2="","",--((IF(Filter_Options!$I$30="",0,COUNTIFS(Itinerary_Tags!$A:$A,$A2,Itinerary_Tags!$B:$B,Filter_Options!$I$30))+IF(Filter_Options!$J$30="",0,COUNTIFS(Itinerary_Tags!$A:$A,$A2,Itinerary_Tags!$B:$B,Filter_Options!$J$30))+IF(Filter_Options!$K$30="",0,COUNTIFS(Itinerary_Tags!$A:$A,$A2,Itinerary_Tags!$B:$B,Filter_Options!$K$30)))>0)) | AF2: =IF($A2="","",--((IF(Filter_Options!$I$31="",0,COUNTIFS(Itinerary_Tags!$A:$A,$A2,Itinerary_Tags!$B:$B,Filter_Options!$I$31))+IF(Filter_Options!$J$31="",0,COUNTIFS(Itinerary_Tags!$A:$A,$A2,Itinerary_Tags!$B:$B,Filter_Options!$J$31))+IF(Filter_Options!$K$31="",0,COUNTIFS(Itinerary_Tags!$A:$A,$A2,Itinerary_Tags!$B:$B,Filter_Options!$K$31)))>0)) | AG2: =IF($A2="","",--((IF(Filter_Options!$I$32="",0,COUNTIFS(Itinerary_Tags!$A:$A,$A2,Itinerary_Tags!$B:$B,Filter_Options!$I$32))+IF(Filter_Options!$J$32="",0,COUNTIFS(Itinerary_Tags!$A:$A,$A2,Itinerary_Tags!$B:$B,Filter_Options!$J$32))+IF(Filter_Options!$K$32="",0,COUNTIFS(Itinerary_Tags!$A:$A,$A2,Itinerary_Tags!$B:$B,Filter_Options!$K$32)))>0)) | AH2: =IF($A2="","",--((IF(Filter_Options!$I$33="",0,COUNTIFS(Itinerary_Tags!$A:$A,$A2,Itinerary_Tags!$B:$B,Filter_Options!$I$33))+IF(Filter_Options!$J$33="",0,COUNTIFS(Itinerary_Tags!$A:$A,$A2,Itinerary_Tags!$B:$B,Filter_Options!$J$33))+IF(Filter_Options!$K$33="",0,COUNTIFS(Itinerary_Tags!$A:$A,$A2,Itinerary_Tags!$B:$B,Filter_Options!$K$33)))>0)) | AI2: =IF($A2="","",--((IF(Filter_Options!$I$34="",0,COUNTIFS(Itinerary_Tags!$A:$A,$A2,Itinerary_Tags!$B:$B,Filter_Options!$I$34))+IF(Filter_Options!$J$34="",0,COUNTIFS(Itinerary_Tags!$A:$A,$A2,Itinerary_Tags!$B:$B,Filter_Options!$J$34))+IF(Filter_Options!$K$34="",0,COUNTIFS(Itinerary_Tags!$A:$A,$A2,Itinerary_Tags!$B:$B,Filter_Options!$K$34)))>0)) | AJ2: =IF($A2="","",--((IF(Filter_Options!$I$35="",0,COUNTIFS(Itinerary_Tags!$A:$A,$A2,Itinerary_Tags!$B:$B,Filter_Options!$I$35))+IF(Filter_Options!$J$35="",0,COUNTIFS(Itinerary_Tags!$A:$A,$A2,Itinerary_Tags!$B:$B,Filter_Options!$J$35))+IF(Filter_Options!$K$35="",0,COUNTIFS(Itinerary_Tags!$A:$A,$A2,Itinerary_Tags!$B:$B,Filter_Options!$K$35)))>0)) | AK2: =IF($A2="","",--((IF(Filter_Options!$I$36="",0,COUNTIFS(Itinerary_Tags!$A:$A,$A2,Itinerary_Tags!$B:$B,Filter_Options!$I$36))+IF(Filter_Options!$J$36="",0,COUNTIFS(Itinerary_Tags!$A:$A,$A2,Itinerary_Tags!$B:$B,Filter_Options!$J$36))+IF(Filter_Options!$K$36="",0,COUNTIFS(Itinerary_Tags!$A:$A,$A2,Itinerary_Tags!$B:$B,Filter_Options!$K$36)))>0)) | AL2: =IF($A2="","",--((IF(Filter_Options!$I$37="",0,COUNTIFS(Itinerary_Tags!$A:$A,$A2,Itinerary_Tags!$B:$B,Filter_Options!$I$37))+IF(Filter_Options!$J$37="",0,COUNTIFS(Itinerary_Tags!$A:$A,$A2,Itinerary_Tags!$B:$B,Filter_Options!$J$37))+IF(Filter_Options!$K$37="",0,COUNTIFS(Itinerary_Tags!$A:$A,$A2,Itinerary_Tags!$B:$B,Filter_Options!$K$37)))>0))
A3: =IF(Itineraries!A3="","",Itineraries!A3) | B3: =IF(Itineraries!A3="","",Itineraries!C3) | C3: =IF($A3="","",--(Itineraries!$J3=Filter_Options!$F$2)) | D3: =IF($A3="","",--(Itineraries!$J3=Filter_Options!$F$3)) | E3: =IF($A3="","",--(Itineraries!$J3=Filter_Options!$F$4)) | F3: =IF($A3="","",--(Itineraries!$J3=Filter_Options!$F$5)) | G3: =IF($A3="","",--(Itineraries!$J3=Filter_Options!$F$6)) | H3: =IF($A3="","",--(Itineraries!$J3=Filter_Options!$F$7)) | I3: =IF($A3="","",--AND(Itineraries!$K3<=Filter_Options!$H$8,Itineraries!$L3>=Filter_Options!$G$8)) | J3: =IF($A3="","",--AND(Itineraries!$K3<=Filter_Options!$H$9,Itineraries!$L3>=Filter_Options!$G$9)) | K3: =IF($A3="","",--AND(Itineraries!$K3<=Filter_Options!$H$10,Itineraries!$L3>=Filter_Options!$G$10)) | L3: =IF($A3="","",--AND(Itineraries!$K3<=Filter_Options!$H$11,Itineraries!$L3>=Filter_Options!$G$11)) | M3: =IF($A3="","",--AND(Itineraries!$K3<=Filter_Options!$H$12,Itineraries!$L3>=Filter_Options!$G$12)) | N3: =IF($A3="","",--AND(Itineraries!$K3<=Filter_Options!$H$13,Itineraries!$L3>=Filter_Options!$G$13)) | O3: =IF($A3="","",--AND(Itineraries!$E3>=Filter_Options!$G$14,Itineraries!$E3<=Filter_Options!$H$14)) | P3: =IF($A3="","",--AND(Itineraries!$E3>=Filter_Options!$G$15,Itineraries!$E3<=Filter_Options!$H$15)) | Q3: =IF($A3="","",--AND(Itineraries!$E3>=Filter_Options!$G$16,Itineraries!$E3<=Filter_Options!$H$16)) | R3: =IF($A3="","",--AND(Itineraries!$E3>=Filter_Options!$G$17,Itineraries!$E3<=Filter_Options!$H$17)) | S3: =IF($A3="","",--AND(Itineraries!$E3>=Filter_Options!$G$18,Itineraries!$E3<=Filter_Options!$H$18)) | T3: =IF($A3="","",--AND(Itineraries!$E3>=Filter_Options!$G$19,Itineraries!$E3<=Filter_Options!$H$19)) | U3: =IF($A3="","",--((IF(Filter_Options!$I$20="",0,COUNTIFS(Itinerary_Tags!$A:$A,$A3,Itinerary_Tags!$B:$B,Filter_Options!$I$20))+IF(Filter_Options!$J$20="",0,COUNTIFS(Itinerary_Tags!$A:$A,$A3,Itinerary_Tags!$B:$B,Filter_Options!$J$20))+IF(Filter_Options!$K$20="",0,COUNTIFS(Itinerary_Tags!$A:$A,$A3,Itinerary_Tags!$B:$B,Filter_Options!$K$20)))>0)) | V3: =IF($A3="","",--((IF(Filter_Options!$I$21="",0,COUNTIFS(Itinerary_Tags!$A:$A,$A3,Itinerary_Tags!$B:$B,Filter_Options!$I$21))+IF(Filter_Options!$J$21="",0,COUNTIFS(Itinerary_Tags!$A:$A,$A3,Itinerary_Tags!$B:$B,Filter_Options!$J$21))+IF(Filter_Options!$K$21="",0,COUNTIFS(Itinerary_Tags!$A:$A,$A3,Itinerary_Tags!$B:$B,Filter_Options!$K$21)))>0)) | W3: =IF($A3="","",--((IF(Filter_Options!$I$22="",0,COUNTIFS(Itinerary_Tags!$A:$A,$A3,Itinerary_Tags!$B:$B,Filter_Options!$I$22))+IF(Filter_Options!$J$22="",0,COUNTIFS(Itinerary_Tags!$A:$A,$A3,Itinerary_Tags!$B:$B,Filter_Options!$J$22))+IF(Filter_Options!$K$22="",0,COUNTIFS(Itinerary_Tags!$A:$A,$A3,Itinerary_Tags!$B:$B,Filter_Options!$K$22)))>0)) | X3: =IF($A3="","",--((IF(Filter_Options!$I$23="",0,COUNTIFS(Itinerary_Tags!$A:$A,$A3,Itinerary_Tags!$B:$B,Filter_Options!$I$23))+IF(Filter_Options!$J$23="",0,COUNTIFS(Itinerary_Tags!$A:$A,$A3,Itinerary_Tags!$B:$B,Filter_Options!$J$23))+IF(Filter_Options!$K$23="",0,COUNTIFS(Itinerary_Tags!$A:$A,$A3,Itinerary_Tags!$B:$B,Filter_Options!$K$23)))>0)) | Y3: =IF($A3="","",--((IF(Filter_Options!$I$24="",0,COUNTIFS(Itinerary_Tags!$A:$A,$A3,Itinerary_Tags!$B:$B,Filter_Options!$I$24))+IF(Filter_Options!$J$24="",0,COUNTIFS(Itinerary_Tags!$A:$A,$A3,Itinerary_Tags!$B:$B,Filter_Options!$J$24))+IF(Filter_Options!$K$24="",0,COUNTIFS(Itinerary_Tags!$A:$A,$A3,Itinerary_Tags!$B:$B,Filter_Options!$K$24)))>0)) | Z3: =IF($A3="","",--((IF(Filter_Options!$I$25="",0,COUNTIFS(Itinerary_Tags!$A:$A,$A3,Itinerary_Tags!$B:$B,Filter_Options!$I$25))+IF(Filter_Options!$J$25="",0,COUNTIFS(Itinerary_Tags!$A:$A,$A3,Itinerary_Tags!$B:$B,Filter_Options!$J$25))+IF(Filter_Options!$K$25="",0,COUNTIFS(Itinerary_Tags!$A:$A,$A3,Itinerary_Tags!$B:$B,Filter_Options!$K$25)))>0)) | AA3: =IF($A3="","",--((IF(Filter_Options!$I$26="",0,COUNTIFS(Itinerary_Tags!$A:$A,$A3,Itinerary_Tags!$B:$B,Filter_Options!$I$26))+IF(Filter_Options!$J$26="",0,COUNTIFS(Itinerary_Tags!$A:$A,$A3,Itinerary_Tags!$B:$B,Filter_Options!$J$26))+IF(Filter_Options!$K$26="",0,COUNTIFS(Itinerary_Tags!$A:$A,$A3,Itinerary_Tags!$B:$B,Filter_Options!$K$26)))>0)) | AB3: =IF($A3="","",--((IF(Filter_Options!$I$27="",0,COUNTIFS(Itinerary_Tags!$A:$A,$A3,Itinerary_Tags!$B:$B,Filter_Options!$I$27))+IF(Filter_Options!$J$27="",0,COUNTIFS(Itinerary_Tags!$A:$A,$A3,Itinerary_Tags!$B:$B,Filter_Options!$J$27))+IF(Filter_Options!$K$27="",0,COUNTIFS(Itinerary_Tags!$A:$A,$A3,Itinerary_Tags!$B:$B,Filter_Options!$K$27)))>0)) | AC3: =IF($A3="","",--((IF(Filter_Options!$I$28="",0,COUNTIFS(Itinerary_Tags!$A:$A,$A3,Itinerary_Tags!$B:$B,Filter_Options!$I$28))+IF(Filter_Options!$J$28="",0,COUNTIFS(Itinerary_Tags!$A:$A,$A3,Itinerary_Tags!$B:$B,Filter_Options!$J$28))+IF(Filter_Options!$K$28="",0,COUNTIFS(Itinerary_Tags!$A:$A,$A3,Itinerary_Tags!$B:$B,Filter_Options!$K$28)))>0)) | AD3: =IF($A3="","",--((IF(Filter_Options!$I$29="",0,COUNTIFS(Itinerary_Tags!$A:$A,$A3,Itinerary_Tags!$B:$B,Filter_Options!$I$29))+IF(Filter_Options!$J$29="",0,COUNTIFS(Itinerary_Tags!$A:$A,$A3,Itinerary_Tags!$B:$B,Filter_Options!$J$29))+IF(Filter_Options!$K$29="",0,COUNTIFS(Itinerary_Tags!$A:$A,$A3,Itinerary_Tags!$B:$B,Filter_Options!$K$29)))>0)) | AE3: =IF($A3="","",--((IF(Filter_Options!$I$30="",0,COUNTIFS(Itinerary_Tags!$A:$A,$A3,Itinerary_Tags!$B:$B,Filter_Options!$I$30))+IF(Filter_Options!$J$30="",0,COUNTIFS(Itinerary_Tags!$A:$A,$A3,Itinerary_Tags!$B:$B,Filter_Options!$J$30))+IF(Filter_Options!$K$30="",0,COUNTIFS(Itinerary_Tags!$A:$A,$A3,Itinerary_Tags!$B:$B,Filter_Options!$K$30)))>0)) | AF3: =IF($A3="","",--((IF(Filter_Options!$I$31="",0,COUNTIFS(Itinerary_Tags!$A:$A,$A3,Itinerary_Tags!$B:$B,Filter_Options!$I$31))+IF(Filter_Options!$J$31="",0,COUNTIFS(Itinerary_Tags!$A:$A,$A3,Itinerary_Tags!$B:$B,Filter_Options!$J$31))+IF(Filter_Options!$K$31="",0,COUNTIFS(Itinerary_Tags!$A:$A,$A3,Itinerary_Tags!$B:$B,Filter_Options!$K$31)))>0)) | AG3: =IF($A3="","",--((IF(Filter_Options!$I$32="",0,COUNTIFS(Itinerary_Tags!$A:$A,$A3,Itinerary_Tags!$B:$B,Filter_Options!$I$32))+IF(Filter_Options!$J$32="",0,COUNTIFS(Itinerary_Tags!$A:$A,$A3,Itinerary_Tags!$B:$B,Filter_Options!$J$32))+IF(Filter_Options!$K$32="",0,COUNTIFS(Itinerary_Tags!$A:$A,$A3,Itinerary_Tags!$B:$B,Filter_Options!$K$32)))>0)) | AH3: =IF($A3="","",--((IF(Filter_Options!$I$33="",0,COUNTIFS(Itinerary_Tags!$A:$A,$A3,Itinerary_Tags!$B:$B,Filter_Options!$I$33))+IF(Filter_Options!$J$33="",0,COUNTIFS(Itinerary_Tags!$A:$A,$A3,Itinerary_Tags!$B:$B,Filter_Options!$J$33))+IF(Filter_Options!$K$33="",0,COUNTIFS(Itinerary_Tags!$A:$A,$A3,Itinerary_Tags!$B:$B,Filter_Options!$K$33)))>0)) | AI3: =IF($A3="","",--((IF(Filter_Options!$I$34="",0,COUNTIFS(Itinerary_Tags!$A:$A,$A3,Itinerary_Tags!$B:$B,Filter_Options!$I$34))+IF(Filter_Options!$J$34="",0,COUNTIFS(Itinerary_Tags!$A:$A,$A3,Itinerary_Tags!$B:$B,Filter_Options!$J$34))+IF(Filter_Options!$K$34="",0,COUNTIFS(Itinerary_Tags!$A:$A,$A3,Itinerary_Tags!$B:$B,Filter_Options!$K$34)))>0)) | AJ3: =IF($A3="","",--((IF(Filter_Options!$I$35="",0,COUNTIFS(Itinerary_Tags!$A:$A,$A3,Itinerary_Tags!$B:$B,Filter_Options!$I$35))+IF(Filter_Options!$J$35="",0,COUNTIFS(Itinerary_Tags!$A:$A,$A3,Itinerary_Tags!$B:$B,Filter_Options!$J$35))+IF(Filter_Options!$K$35="",0,COUNTIFS(Itinerary_Tags!$A:$A,$A3,Itinerary_Tags!$B:$B,Filter_Options!$K$35)))>0)) | AK3: =IF($A3="","",--((IF(Filter_Options!$I$36="",0,COUNTIFS(Itinerary_Tags!$A:$A,$A3,Itinerary_Tags!$B:$B,Filter_Options!$I$36))+IF(Filter_Options!$J$36="",0,COUNTIFS(Itinerary_Tags!$A:$A,$A3,Itinerary_Tags!$B:$B,Filter_Options!$J$36))+IF(Filter_Options!$K$36="",0,COUNTIFS(Itinerary_Tags!$A:$A,$A3,Itinerary_Tags!$B:$B,Filter_Options!$K$36)))>0)) | AL3: =IF($A3="","",--((IF(Filter_Options!$I$37="",0,COUNTIFS(Itinerary_Tags!$A:$A,$A3,Itinerary_Tags!$B:$B,Filter_Options!$I$37))+IF(Filter_Options!$J$37="",0,COUNTIFS(Itinerary_Tags!$A:$A,$A3,Itinerary_Tags!$B:$B,Filter_Options!$J$37))+IF(Filter_Options!$K$37="",0,COUNTIFS(Itinerary_Tags!$A:$A,$A3,Itinerary_Tags!$B:$B,Filter_Options!$K$37)))>0))
A4: =IF(Itineraries!A4="","",Itineraries!A4) | B4: =IF(Itineraries!A4="","",Itineraries!C4) | C4: =IF($A4="","",--(Itineraries!$J4=Filter_Options!$F$2)) | D4: =IF($A4="","",--(Itineraries!$J4=Filter_Options!$F$3)) | E4: =IF($A4="","",--(Itineraries!$J4=Filter_Options!$F$4)) | F4: =IF($A4="","",--(Itineraries!$J4=Filter_Options!$F$5)) | G4: =IF($A4="","",--(Itineraries!$J4=Filter_Options!$F$6)) | H4: =IF($A4="","",--(Itineraries!$J4=Filter_Options!$F$7)) | I4: =IF($A4="","",--AND(Itineraries!$K4<=Filter_Options!$H$8,Itineraries!$L4>=Filter_Options!$G$8)) | J4: =IF($A4="","",--AND(Itineraries!$K4<=Filter_Options!$H$9,Itineraries!$L4>=Filter_Options!$G$9)) | K4: =IF($A4="","",--AND(Itineraries!$K4<=Filter_Options!$H$10,Itineraries!$L4>=Filter_Options!$G$10)) | L4: =IF($A4="","",--AND(Itineraries!$K4<=Filter_Options!$H$11,Itineraries!$L4>=Filter_Options!$G$11)) | M4: =IF($A4="","",--AND(Itineraries!$K4<=Filter_Options!$H$12,Itineraries!$L4>=Filter_Options!$G$12)) | N4: =IF($A4="","",--AND(Itineraries!$K4<=Filter_Options!$H$13,Itineraries!$L4>=Filter_Options!$G$13)) | O4: =IF($A4="","",--AND(Itineraries!$E4>=Filter_Options!$G$14,Itineraries!$E4<=Filter_Options!$H$14)) | P4: =IF($A4="","",--AND(Itineraries!$E4>=Filter_Options!$G$15,Itineraries!$E4<=Filter_Options!$H$15)) | Q4: =IF($A4="","",--AND(Itineraries!$E4>=Filter_Options!$G$16,Itineraries!$E4<=Filter_Options!$H$16)) | R4: =IF($A4="","",--AND(Itineraries!$E4>=Filter_Options!$G$17,Itineraries!$E4<=Filter_Options!$H$17)) | S4: =IF($A4="","",--AND(Itineraries!$E4>=Filter_Options!$G$18,Itineraries!$E4<=Filter_Options!$H$18)) | T4: =IF($A4="","",--AND(Itineraries!$E4>=Filter_Options!$G$19,Itineraries!$E4<=Filter_Options!$H$19)) | U4: =IF($A4="","",--((IF(Filter_Options!$I$20="",0,COUNTIFS(Itinerary_Tags!$A:$A,$A4,Itinerary_Tags!$B:$B,Filter_Options!$I$20))+IF(Filter_Options!$J$20="",0,COUNTIFS(Itinerary_Tags!$A:$A,$A4,Itinerary_Tags!$B:$B,Filter_Options!$J$20))+IF(Filter_Options!$K$20="",0,COUNTIFS(Itinerary_Tags!$A:$A,$A4,Itinerary_Tags!$B:$B,Filter_Options!$K$20)))>0)) | V4: =IF($A4="","",--((IF(Filter_Options!$I$21="",0,COUNTIFS(Itinerary_Tags!$A:$A,$A4,Itinerary_Tags!$B:$B,Filter_Options!$I$21))+IF(Filter_Options!$J$21="",0,COUNTIFS(Itinerary_Tags!$A:$A,$A4,Itinerary_Tags!$B:$B,Filter_Options!$J$21))+IF(Filter_Options!$K$21="",0,COUNTIFS(Itinerary_Tags!$A:$A,$A4,Itinerary_Tags!$B:$B,Filter_Options!$K$21)))>0)) | W4: =IF($A4="","",--((IF(Filter_Options!$I$22="",0,COUNTIFS(Itinerary_Tags!$A:$A,$A4,Itinerary_Tags!$B:$B,Filter_Options!$I$22))+IF(Filter_Options!$J$22="",0,COUNTIFS(Itinerary_Tags!$A:$A,$A4,Itinerary_Tags!$B:$B,Filter_Options!$J$22))+IF(Filter_Options!$K$22="",0,COUNTIFS(Itinerary_Tags!$A:$A,$A4,Itinerary_Tags!$B:$B,Filter_Options!$K$22)))>0)) | X4: =IF($A4="","",--((IF(Filter_Options!$I$23="",0,COUNTIFS(Itinerary_Tags!$A:$A,$A4,Itinerary_Tags!$B:$B,Filter_Options!$I$23))+IF(Filter_Options!$J$23="",0,COUNTIFS(Itinerary_Tags!$A:$A,$A4,Itinerary_Tags!$B:$B,Filter_Options!$J$23))+IF(Filter_Options!$K$23="",0,COUNTIFS(Itinerary_Tags!$A:$A,$A4,Itinerary_Tags!$B:$B,Filter_Options!$K$23)))>0)) | Y4: =IF($A4="","",--((IF(Filter_Options!$I$24="",0,COUNTIFS(Itinerary_Tags!$A:$A,$A4,Itinerary_Tags!$B:$B,Filter_Options!$I$24))+IF(Filter_Options!$J$24="",0,COUNTIFS(Itinerary_Tags!$A:$A,$A4,Itinerary_Tags!$B:$B,Filter_Options!$J$24))+IF(Filter_Options!$K$24="",0,COUNTIFS(Itinerary_Tags!$A:$A,$A4,Itinerary_Tags!$B:$B,Filter_Options!$K$24)))>0)) | Z4: =IF($A4="","",--((IF(Filter_Options!$I$25="",0,COUNTIFS(Itinerary_Tags!$A:$A,$A4,Itinerary_Tags!$B:$B,Filter_Options!$I$25))+IF(Filter_Options!$J$25="",0,COUNTIFS(Itinerary_Tags!$A:$A,$A4,Itinerary_Tags!$B:$B,Filter_Options!$J$25))+IF(Filter_Options!$K$25="",0,COUNTIFS(Itinerary_Tags!$A:$A,$A4,Itinerary_Tags!$B:$B,Filter_Options!$K$25)))>0)) | AA4: =IF($A4="","",--((IF(Filter_Options!$I$26="",0,COUNTIFS(Itinerary_Tags!$A:$A,$A4,Itinerary_Tags!$B:$B,Filter_Options!$I$26))+IF(Filter_Options!$J$26="",0,COUNTIFS(Itinerary_Tags!$A:$A,$A4,Itinerary_Tags!$B:$B,Filter_Options!$J$26))+IF(Filter_Options!$K$26="",0,COUNTIFS(Itinerary_Tags!$A:$A,$A4,Itinerary_Tags!$B:$B,Filter_Options!$K$26)))>0)) | AB4: =IF($A4="","",--((IF(Filter_Options!$I$27="",0,COUNTIFS(Itinerary_Tags!$A:$A,$A4,Itinerary_Tags!$B:$B,Filter_Options!$I$27))+IF(Filter_Options!$J$27="",0,COUNTIFS(Itinerary_Tags!$A:$A,$A4,Itinerary_Tags!$B:$B,Filter_Options!$J$27))+IF(Filter_Options!$K$27="",0,COUNTIFS(Itinerary_Tags!$A:$A,$A4,Itinerary_Tags!$B:$B,Filter_Options!$K$27)))>0)) | AC4: =IF($A4="","",--((IF(Filter_Options!$I$28="",0,COUNTIFS(Itinerary_Tags!$A:$A,$A4,Itinerary_Tags!$B:$B,Filter_Options!$I$28))+IF(Filter_Options!$J$28="",0,COUNTIFS(Itinerary_Tags!$A:$A,$A4,Itinerary_Tags!$B:$B,Filter_Options!$J$28))+IF(Filter_Options!$K$28="",0,COUNTIFS(Itinerary_Tags!$A:$A,$A4,Itinerary_Tags!$B:$B,Filter_Options!$K$28)))>0)) | AD4: =IF($A4="","",--((IF(Filter_Options!$I$29="",0,COUNTIFS(Itinerary_Tags!$A:$A,$A4,Itinerary_Tags!$B:$B,Filter_Options!$I$29))+IF(Filter_Options!$J$29="",0,COUNTIFS(Itinerary_Tags!$A:$A,$A4,Itinerary_Tags!$B:$B,Filter_Options!$J$29))+IF(Filter_Options!$K$29="",0,COUNTIFS(Itinerary_Tags!$A:$A,$A4,Itinerary_Tags!$B:$B,Filter_Options!$K$29)))>0)) | AE4: =IF($A4="","",--((IF(Filter_Options!$I$30="",0,COUNTIFS(Itinerary_Tags!$A:$A,$A4,Itinerary_Tags!$B:$B,Filter_Options!$I$30))+IF(Filter_Options!$J$30="",0,COUNTIFS(Itinerary_Tags!$A:$A,$A4,Itinerary_Tags!$B:$B,Filter_Options!$J$30))+IF(Filter_Options!$K$30="",0,COUNTIFS(Itinerary_Tags!$A:$A,$A4,Itinerary_Tags!$B:$B,Filter_Options!$K$30)))>0)) | AF4: =IF($A4="","",--((IF(Filter_Options!$I$31="",0,COUNTIFS(Itinerary_Tags!$A:$A,$A4,Itinerary_Tags!$B:$B,Filter_Options!$I$31))+IF(Filter_Options!$J$31="",0,COUNTIFS(Itinerary_Tags!$A:$A,$A4,Itinerary_Tags!$B:$B,Filter_Options!$J$31))+IF(Filter_Options!$K$31="",0,COUNTIFS(Itinerary_Tags!$A:$A,$A4,Itinerary_Tags!$B:$B,Filter_Options!$K$31)))>0)) | AG4: =IF($A4="","",--((IF(Filter_Options!$I$32="",0,COUNTIFS(Itinerary_Tags!$A:$A,$A4,Itinerary_Tags!$B:$B,Filter_Options!$I$32))+IF(Filter_Options!$J$32="",0,COUNTIFS(Itinerary_Tags!$A:$A,$A4,Itinerary_Tags!$B:$B,Filter_Options!$J$32))+IF(Filter_Options!$K$32="",0,COUNTIFS(Itinerary_Tags!$A:$A,$A4,Itinerary_Tags!$B:$B,Filter_Options!$K$32)))>0)) | AH4: =IF($A4="","",--((IF(Filter_Options!$I$33="",0,COUNTIFS(Itinerary_Tags!$A:$A,$A4,Itinerary_Tags!$B:$B,Filter_Options!$I$33))+IF(Filter_Options!$J$33="",0,COUNTIFS(Itinerary_Tags!$A:$A,$A4,Itinerary_Tags!$B:$B,Filter_Options!$J$33))+IF(Filter_Options!$K$33="",0,COUNTIFS(Itinerary_Tags!$A:$A,$A4,Itinerary_Tags!$B:$B,Filter_Options!$K$33)))>0)) | AI4: =IF($A4="","",--((IF(Filter_Options!$I$34="",0,COUNTIFS(Itinerary_Tags!$A:$A,$A4,Itinerary_Tags!$B:$B,Filter_Options!$I$34))+IF(Filter_Options!$J$34="",0,COUNTIFS(Itinerary_Tags!$A:$A,$A4,Itinerary_Tags!$B:$B,Filter_Options!$J$34))+IF(Filter_Options!$K$34="",0,COUNTIFS(Itinerary_Tags!$A:$A,$A4,Itinerary_Tags!$B:$B,Filter_Options!$K$34)))>0)) | AJ4: =IF($A4="","",--((IF(Filter_Options!$I$35="",0,COUNTIFS(Itinerary_Tags!$A:$A,$A4,Itinerary_Tags!$B:$B,Filter_Options!$I$35))+IF(Filter_Options!$J$35="",0,COUNTIFS(Itinerary_Tags!$A:$A,$A4,Itinerary_Tags!$B:$B,Filter_Options!$J$35))+IF(Filter_Options!$K$35="",0,COUNTIFS(Itinerary_Tags!$A:$A,$A4,Itinerary_Tags!$B:$B,Filter_Options!$K$35)))>0)) | AK4: =IF($A4="","",--((IF(Filter_Options!$I$36="",0,COUNTIFS(Itinerary_Tags!$A:$A,$A4,Itinerary_Tags!$B:$B,Filter_Options!$I$36))+IF(Filter_Options!$J$36="",0,COUNTIFS(Itinerary_Tags!$A:$A,$A4,Itinerary_Tags!$B:$B,Filter_Options!$J$36))+IF(Filter_Options!$K$36="",0,COUNTIFS(Itinerary_Tags!$A:$A,$A4,Itinerary_Tags!$B:$B,Filter_Options!$K$36)))>0)) | AL4: =IF($A4="","",--((IF(Filter_Options!$I$37="",0,COUNTIFS(Itinerary_Tags!$A:$A,$A4,Itinerary_Tags!$B:$B,Filter_Options!$I$37))+IF(Filter_Options!$J$37="",0,COUNTIFS(Itinerary_Tags!$A:$A,$A4,Itinerary_Tags!$B:$B,Filter_Options!$J$37))+IF(Filter_Options!$K$37="",0,COUNTIFS(Itinerary_Tags!$A:$A,$A4,Itinerary_Tags!$B:$B,Filter_Options!$K$37)))>0))
A5: =IF(Itineraries!A5="","",Itineraries!A5) | B5: =IF(Itineraries!A5="","",Itineraries!C5) | C5: =IF($A5="","",--(Itineraries!$J5=Filter_Options!$F$2)) | D5: =IF($A5="","",--(Itineraries!$J5=Filter_Options!$F$3)) | E5: =IF($A5="","",--(Itineraries!$J5=Filter_Options!$F$4)) | F5: =IF($A5="","",--(Itineraries!$J5=Filter_Options!$F$5)) | G5: =IF($A5="","",--(Itineraries!$J5=Filter_Options!$F$6)) | H5: =IF($A5="","",--(Itineraries!$J5=Filter_Options!$F$7)) | I5: =IF($A5="","",--AND(Itineraries!$K5<=Filter_Options!$H$8,Itineraries!$L5>=Filter_Options!$G$8)) | J5: =IF($A5="","",--AND(Itineraries!$K5<=Filter_Options!$H$9,Itineraries!$L5>=Filter_Options!$G$9)) | K5: =IF($A5="","",--AND(Itineraries!$K5<=Filter_Options!$H$10,Itineraries!$L5>=Filter_Options!$G$10)) | L5: =IF($A5="","",--AND(Itineraries!$K5<=Filter_Options!$H$11,Itineraries!$L5>=Filter_Options!$G$11)) | M5: =IF($A5="","",--AND(Itineraries!$K5<=Filter_Options!$H$12,Itineraries!$L5>=Filter_Options!$G$12)) | N5: =IF($A5="","",--AND(Itineraries!$K5<=Filter_Options!$H$13,Itineraries!$L5>=Filter_Options!$G$13)) | O5: =IF($A5="","",--AND(Itineraries!$E5>=Filter_Options!$G$14,Itineraries!$E5<=Filter_Options!$H$14)) | P5: =IF($A5="","",--AND(Itineraries!$E5>=Filter_Options!$G$15,Itineraries!$E5<=Filter_Options!$H$15)) | Q5: =IF($A5="","",--AND(Itineraries!$E5>=Filter_Options!$G$16,Itineraries!$E5<=Filter_Options!$H$16)) | R5: =IF($A5="","",--AND(Itineraries!$E5>=Filter_Options!$G$17,Itineraries!$E5<=Filter_Options!$H$17)) | S5: =IF($A5="","",--AND(Itineraries!$E5>=Filter_Options!$G$18,Itineraries!$E5<=Filter_Options!$H$18)) | T5: =IF($A5="","",--AND(Itineraries!$E5>=Filter_Options!$G$19,Itineraries!$E5<=Filter_Options!$H$19)) | U5: =IF($A5="","",--((IF(Filter_Options!$I$20="",0,COUNTIFS(Itinerary_Tags!$A:$A,$A5,Itinerary_Tags!$B:$B,Filter_Options!$I$20))+IF(Filter_Options!$J$20="",0,COUNTIFS(Itinerary_Tags!$A:$A,$A5,Itinerary_Tags!$B:$B,Filter_Options!$J$20))+IF(Filter_Options!$K$20="",0,COUNTIFS(Itinerary_Tags!$A:$A,$A5,Itinerary_Tags!$B:$B,Filter_Options!$K$20)))>0)) | V5: =IF($A5="","",--((IF(Filter_Options!$I$21="",0,COUNTIFS(Itinerary_Tags!$A:$A,$A5,Itinerary_Tags!$B:$B,Filter_Options!$I$21))+IF(Filter_Options!$J$21="",0,COUNTIFS(Itinerary_Tags!$A:$A,$A5,Itinerary_Tags!$B:$B,Filter_Options!$J$21))+IF(Filter_Options!$K$21="",0,COUNTIFS(Itinerary_Tags!$A:$A,$A5,Itinerary_Tags!$B:$B,Filter_Options!$K$21)))>0)) | W5: =IF($A5="","",--((IF(Filter_Options!$I$22="",0,COUNTIFS(Itinerary_Tags!$A:$A,$A5,Itinerary_Tags!$B:$B,Filter_Options!$I$22))+IF(Filter_Options!$J$22="",0,COUNTIFS(Itinerary_Tags!$A:$A,$A5,Itinerary_Tags!$B:$B,Filter_Options!$J$22))+IF(Filter_Options!$K$22="",0,COUNTIFS(Itinerary_Tags!$A:$A,$A5,Itinerary_Tags!$B:$B,Filter_Options!$K$22)))>0)) | X5: =IF($A5="","",--((IF(Filter_Options!$I$23="",0,COUNTIFS(Itinerary_Tags!$A:$A,$A5,Itinerary_Tags!$B:$B,Filter_Options!$I$23))+IF(Filter_Options!$J$23="",0,COUNTIFS(Itinerary_Tags!$A:$A,$A5,Itinerary_Tags!$B:$B,Filter_Options!$J$23))+IF(Filter_Options!$K$23="",0,COUNTIFS(Itinerary_Tags!$A:$A,$A5,Itinerary_Tags!$B:$B,Filter_Options!$K$23)))>0)) | Y5: =IF($A5="","",--((IF(Filter_Options!$I$24="",0,COUNTIFS(Itinerary_Tags!$A:$A,$A5,Itinerary_Tags!$B:$B,Filter_Options!$I$24))+IF(Filter_Options!$J$24="",0,COUNTIFS(Itinerary_Tags!$A:$A,$A5,Itinerary_Tags!$B:$B,Filter_Options!$J$24))+IF(Filter_Options!$K$24="",0,COUNTIFS(Itinerary_Tags!$A:$A,$A5,Itinerary_Tags!$B:$B,Filter_Options!$K$24)))>0)) | Z5: =IF($A5="","",--((IF(Filter_Options!$I$25="",0,COUNTIFS(Itinerary_Tags!$A:$A,$A5,Itinerary_Tags!$B:$B,Filter_Options!$I$25))+IF(Filter_Options!$J$25="",0,COUNTIFS(Itinerary_Tags!$A:$A,$A5,Itinerary_Tags!$B:$B,Filter_Options!$J$25))+IF(Filter_Options!$K$25="",0,COUNTIFS(Itinerary_Tags!$A:$A,$A5,Itinerary_Tags!$B:$B,Filter_Options!$K$25)))>0)) | AA5: =IF($A5="","",--((IF(Filter_Options!$I$26="",0,COUNTIFS(Itinerary_Tags!$A:$A,$A5,Itinerary_Tags!$B:$B,Filter_Options!$I$26))+IF(Filter_Options!$J$26="",0,COUNTIFS(Itinerary_Tags!$A:$A,$A5,Itinerary_Tags!$B:$B,Filter_Options!$J$26))+IF(Filter_Options!$K$26="",0,COUNTIFS(Itinerary_Tags!$A:$A,$A5,Itinerary_Tags!$B:$B,Filter_Options!$K$26)))>0)) | AB5: =IF($A5="","",--((IF(Filter_Options!$I$27="",0,COUNTIFS(Itinerary_Tags!$A:$A,$A5,Itinerary_Tags!$B:$B,Filter_Options!$I$27))+IF(Filter_Options!$J$27="",0,COUNTIFS(Itinerary_Tags!$A:$A,$A5,Itinerary_Tags!$B:$B,Filter_Options!$J$27))+IF(Filter_Options!$K$27="",0,COUNTIFS(Itinerary_Tags!$A:$A,$A5,Itinerary_Tags!$B:$B,Filter_Options!$K$27)))>0)) | AC5: =IF($A5="","",--((IF(Filter_Options!$I$28="",0,COUNTIFS(Itinerary_Tags!$A:$A,$A5,Itinerary_Tags!$B:$B,Filter_Options!$I$28))+IF(Filter_Options!$J$28="",0,COUNTIFS(Itinerary_Tags!$A:$A,$A5,Itinerary_Tags!$B:$B,Filter_Options!$J$28))+IF(Filter_Options!$K$28="",0,COUNTIFS(Itinerary_Tags!$A:$A,$A5,Itinerary_Tags!$B:$B,Filter_Options!$K$28)))>0)) | AD5: =IF($A5="","",--((IF(Filter_Options!$I$29="",0,COUNTIFS(Itinerary_Tags!$A:$A,$A5,Itinerary_Tags!$B:$B,Filter_Options!$I$29))+IF(Filter_Options!$J$29="",0,COUNTIFS(Itinerary_Tags!$A:$A,$A5,Itinerary_Tags!$B:$B,Filter_Options!$J$29))+IF(Filter_Options!$K$29="",0,COUNTIFS(Itinerary_Tags!$A:$A,$A5,Itinerary_Tags!$B:$B,Filter_Options!$K$29)))>0)) | AE5: =IF($A5="","",--((IF(Filter_Options!$I$30="",0,COUNTIFS(Itinerary_Tags!$A:$A,$A5,Itinerary_Tags!$B:$B,Filter_Options!$I$30))+IF(Filter_Options!$J$30="",0,COUNTIFS(Itinerary_Tags!$A:$A,$A5,Itinerary_Tags!$B:$B,Filter_Options!$J$30))+IF(Filter_Options!$K$30="",0,COUNTIFS(Itinerary_Tags!$A:$A,$A5,Itinerary_Tags!$B:$B,Filter_Options!$K$30)))>0)) | AF5: =IF($A5="","",--((IF(Filter_Options!$I$31="",0,COUNTIFS(Itinerary_Tags!$A:$A,$A5,Itinerary_Tags!$B:$B,Filter_Options!$I$31))+IF(Filter_Options!$J$31="",0,COUNTIFS(Itinerary_Tags!$A:$A,$A5,Itinerary_Tags!$B:$B,Filter_Options!$J$31))+IF(Filter_Options!$K$31="",0,COUNTIFS(Itinerary_Tags!$A:$A,$A5,Itinerary_Tags!$B:$B,Filter_Options!$K$31)))>0)) | AG5: =IF($A5="","",--((IF(Filter_Options!$I$32="",0,COUNTIFS(Itinerary_Tags!$A:$A,$A5,Itinerary_Tags!$B:$B,Filter_Options!$I$32))+IF(Filter_Options!$J$32="",0,COUNTIFS(Itinerary_Tags!$A:$A,$A5,Itinerary_Tags!$B:$B,Filter_Options!$J$32))+IF(Filter_Options!$K$32="",0,COUNTIFS(Itinerary_Tags!$A:$A,$A5,Itinerary_Tags!$B:$B,Filter_Options!$K$32)))>0)) | AH5: =IF($A5="","",--((IF(Filter_Options!$I$33="",0,COUNTIFS(Itinerary_Tags!$A:$A,$A5,Itinerary_Tags!$B:$B,Filter_Options!$I$33))+IF(Filter_Options!$J$33="",0,COUNTIFS(Itinerary_Tags!$A:$A,$A5,Itinerary_Tags!$B:$B,Filter_Options!$J$33))+IF(Filter_Options!$K$33="",0,COUNTIFS(Itinerary_Tags!$A:$A,$A5,Itinerary_Tags!$B:$B,Filter_Options!$K$33)))>0)) | AI5: =IF($A5="","",--((IF(Filter_Options!$I$34="",0,COUNTIFS(Itinerary_Tags!$A:$A,$A5,Itinerary_Tags!$B:$B,Filter_Options!$I$34))+IF(Filter_Options!$J$34="",0,COUNTIFS(Itinerary_Tags!$A:$A,$A5,Itinerary_Tags!$B:$B,Filter_Options!$J$34))+IF(Filter_Options!$K$34="",0,COUNTIFS(Itinerary_Tags!$A:$A,$A5,Itinerary_Tags!$B:$B,Filter_Options!$K$34)))>0)) | AJ5: =IF($A5="","",--((IF(Filter_Options!$I$35="",0,COUNTIFS(Itinerary_Tags!$A:$A,$A5,Itinerary_Tags!$B:$B,Filter_Options!$I$35))+IF(Filter_Options!$J$35="",0,COUNTIFS(Itinerary_Tags!$A:$A,$A5,Itinerary_Tags!$B:$B,Filter_Options!$J$35))+IF(Filter_Options!$K$35="",0,COUNTIFS(Itinerary_Tags!$A:$A,$A5,Itinerary_Tags!$B:$B,Filter_Options!$K$35)))>0)) | AK5: =IF($A5="","",--((IF(Filter_Options!$I$36="",0,COUNTIFS(Itinerary_Tags!$A:$A,$A5,Itinerary_Tags!$B:$B,Filter_Options!$I$36))+IF(Filter_Options!$J$36="",0,COUNTIFS(Itinerary_Tags!$A:$A,$A5,Itinerary_Tags!$B:$B,Filter_Options!$J$36))+IF(Filter_Options!$K$36="",0,COUNTIFS(Itinerary_Tags!$A:$A,$A5,Itinerary_Tags!$B:$B,Filter_Options!$K$36)))>0)) | AL5: =IF($A5="","",--((IF(Filter_Options!$I$37="",0,COUNTIFS(Itinerary_Tags!$A:$A,$A5,Itinerary_Tags!$B:$B,Filter_Options!$I$37))+IF(Filter_Options!$J$37="",0,COUNTIFS(Itinerary_Tags!$A:$A,$A5,Itinerary_Tags!$B:$B,Filter_Options!$J$37))+IF(Filter_Options!$K$37="",0,COUNTIFS(Itinerary_Tags!$A:$A,$A5,Itinerary_Tags!$B:$B,Filter_Options!$K$37)))>0))
A6: =IF(Itineraries!A6="","",Itineraries!A6) | B6: =IF(Itineraries!A6="","",Itineraries!C6) | C6: =IF($A6="","",--(Itineraries!$J6=Filter_Options!$F$2)) | D6: =IF($A6="","",--(Itineraries!$J6=Filter_Options!$F$3)) | E6: =IF($A6="","",--(Itineraries!$J6=Filter_Options!$F$4)) | F6: =IF($A6="","",--(Itineraries!$J6=Filter_Options!$F$5)) | G6: =IF($A6="","",--(Itineraries!$J6=Filter_Options!$F$6)) | H6: =IF($A6="","",--(Itineraries!$J6=Filter_Options!$F$7)) | I6: =IF($A6="","",--AND(Itineraries!$K6<=Filter_Options!$H$8,Itineraries!$L6>=Filter_Options!$G$8)) | J6: =IF($A6="","",--AND(Itineraries!$K6<=Filter_Options!$H$9,Itineraries!$L6>=Filter_Options!$G$9)) | K6: =IF($A6="","",--AND(Itineraries!$K6<=Filter_Options!$H$10,Itineraries!$L6>=Filter_Options!$G$10)) | L6: =IF($A6="","",--AND(Itineraries!$K6<=Filter_Options!$H$11,Itineraries!$L6>=Filter_Options!$G$11)) | M6: =IF($A6="","",--AND(Itineraries!$K6<=Filter_Options!$H$12,Itineraries!$L6>=Filter_Options!$G$12)) | N6: =IF($A6="","",--AND(Itineraries!$K6<=Filter_Options!$H$13,Itineraries!$L6>=Filter_Options!$G$13)) | O6: =IF($A6="","",--AND(Itineraries!$E6>=Filter_Options!$G$14,Itineraries!$E6<=Filter_Options!$H$14)) | P6: =IF($A6="","",--AND(Itineraries!$E6>=Filter_Options!$G$15,Itineraries!$E6<=Filter_Options!$H$15)) | Q6: =IF($A6="","",--AND(Itineraries!$E6>=Filter_Options!$G$16,Itineraries!$E6<=Filter_Options!$H$16)) | R6: =IF($A6="","",--AND(Itineraries!$E6>=Filter_Options!$G$17,Itineraries!$E6<=Filter_Options!$H$17)) | S6: =IF($A6="","",--AND(Itineraries!$E6>=Filter_Options!$G$18,Itineraries!$E6<=Filter_Options!$H$18)) | T6: =IF($A6="","",--AND(Itineraries!$E6>=Filter_Options!$G$19,Itineraries!$E6<=Filter_Options!$H$19)) | U6: =IF($A6="","",--((IF(Filter_Options!$I$20="",0,COUNTIFS(Itinerary_Tags!$A:$A,$A6,Itinerary_Tags!$B:$B,Filter_Options!$I$20))+IF(Filter_Options!$J$20="",0,COUNTIFS(Itinerary_Tags!$A:$A,$A6,Itinerary_Tags!$B:$B,Filter_Options!$J$20))+IF(Filter_Options!$K$20="",0,COUNTIFS(Itinerary_Tags!$A:$A,$A6,Itinerary_Tags!$B:$B,Filter_Options!$K$20)))>0)) | V6: =IF($A6="","",--((IF(Filter_Options!$I$21="",0,COUNTIFS(Itinerary_Tags!$A:$A,$A6,Itinerary_Tags!$B:$B,Filter_Options!$I$21))+IF(Filter_Options!$J$21="",0,COUNTIFS(Itinerary_Tags!$A:$A,$A6,Itinerary_Tags!$B:$B,Filter_Options!$J$21))+IF(Filter_Options!$K$21="",0,COUNTIFS(Itinerary_Tags!$A:$A,$A6,Itinerary_Tags!$B:$B,Filter_Options!$K$21)))>0)) | W6: =IF($A6="","",--((IF(Filter_Options!$I$22="",0,COUNTIFS(Itinerary_Tags!$A:$A,$A6,Itinerary_Tags!$B:$B,Filter_Options!$I$22))+IF(Filter_Options!$J$22="",0,COUNTIFS(Itinerary_Tags!$A:$A,$A6,Itinerary_Tags!$B:$B,Filter_Options!$J$22))+IF(Filter_Options!$K$22="",0,COUNTIFS(Itinerary_Tags!$A:$A,$A6,Itinerary_Tags!$B:$B,Filter_Options!$K$22)))>0)) | X6: =IF($A6="","",--((IF(Filter_Options!$I$23="",0,COUNTIFS(Itinerary_Tags!$A:$A,$A6,Itinerary_Tags!$B:$B,Filter_Options!$I$23))+IF(Filter_Options!$J$23="",0,COUNTIFS(Itinerary_Tags!$A:$A,$A6,Itinerary_Tags!$B:$B,Filter_Options!$J$23))+IF(Filter_Options!$K$23="",0,COUNTIFS(Itinerary_Tags!$A:$A,$A6,Itinerary_Tags!$B:$B,Filter_Options!$K$23)))>0)) | Y6: =IF($A6="","",--((IF(Filter_Options!$I$24="",0,COUNTIFS(Itinerary_Tags!$A:$A,$A6,Itinerary_Tags!$B:$B,Filter_Options!$I$24))+IF(Filter_Options!$J$24="",0,COUNTIFS(Itinerary_Tags!$A:$A,$A6,Itinerary_Tags!$B:$B,Filter_Options!$J$24))+IF(Filter_Options!$K$24="",0,COUNTIFS(Itinerary_Tags!$A:$A,$A6,Itinerary_Tags!$B:$B,Filter_Options!$K$24)))>0)) | Z6: =IF($A6="","",--((IF(Filter_Options!$I$25="",0,COUNTIFS(Itinerary_Tags!$A:$A,$A6,Itinerary_Tags!$B:$B,Filter_Options!$I$25))+IF(Filter_Options!$J$25="",0,COUNTIFS(Itinerary_Tags!$A:$A,$A6,Itinerary_Tags!$B:$B,Filter_Options!$J$25))+IF(Filter_Options!$K$25="",0,COUNTIFS(Itinerary_Tags!$A:$A,$A6,Itinerary_Tags!$B:$B,Filter_Options!$K$25)))>0)) | AA6: =IF($A6="","",--((IF(Filter_Options!$I$26="",0,COUNTIFS(Itinerary_Tags!$A:$A,$A6,Itinerary_Tags!$B:$B,Filter_Options!$I$26))+IF(Filter_Options!$J$26="",0,COUNTIFS(Itinerary_Tags!$A:$A,$A6,Itinerary_Tags!$B:$B,Filter_Options!$J$26))+IF(Filter_Options!$K$26="",0,COUNTIFS(Itinerary_Tags!$A:$A,$A6,Itinerary_Tags!$B:$B,Filter_Options!$K$26)))>0)) | AB6: =IF($A6="","",--((IF(Filter_Options!$I$27="",0,COUNTIFS(Itinerary_Tags!$A:$A,$A6,Itinerary_Tags!$B:$B,Filter_Options!$I$27))+IF(Filter_Options!$J$27="",0,COUNTIFS(Itinerary_Tags!$A:$A,$A6,Itinerary_Tags!$B:$B,Filter_Options!$J$27))+IF(Filter_Options!$K$27="",0,COUNTIFS(Itinerary_Tags!$A:$A,$A6,Itinerary_Tags!$B:$B,Filter_Options!$K$27)))>0)) | AC6: =IF($A6="","",--((IF(Filter_Options!$I$28="",0,COUNTIFS(Itinerary_Tags!$A:$A,$A6,Itinerary_Tags!$B:$B,Filter_Options!$I$28))+IF(Filter_Options!$J$28="",0,COUNTIFS(Itinerary_Tags!$A:$A,$A6,Itinerary_Tags!$B:$B,Filter_Options!$J$28))+IF(Filter_Options!$K$28="",0,COUNTIFS(Itinerary_Tags!$A:$A,$A6,Itinerary_Tags!$B:$B,Filter_Options!$K$28)))>0)) | AD6: =IF($A6="","",--((IF(Filter_Options!$I$29="",0,COUNTIFS(Itinerary_Tags!$A:$A,$A6,Itinerary_Tags!$B:$B,Filter_Options!$I$29))+IF(Filter_Options!$J$29="",0,COUNTIFS(Itinerary_Tags!$A:$A,$A6,Itinerary_Tags!$B:$B,Filter_Options!$J$29))+IF(Filter_Options!$K$29="",0,COUNTIFS(Itinerary_Tags!$A:$A,$A6,Itinerary_Tags!$B:$B,Filter_Options!$K$29)))>0)) | AE6: =IF($A6="","",--((IF(Filter_Options!$I$30="",0,COUNTIFS(Itinerary_Tags!$A:$A,$A6,Itinerary_Tags!$B:$B,Filter_Options!$I$30))+IF(Filter_Options!$J$30="",0,COUNTIFS(Itinerary_Tags!$A:$A,$A6,Itinerary_Tags!$B:$B,Filter_Options!$J$30))+IF(Filter_Options!$K$30="",0,COUNTIFS(Itinerary_Tags!$A:$A,$A6,Itinerary_Tags!$B:$B,Filter_Options!$K$30)))>0)) | AF6: =IF($A6="","",--((IF(Filter_Options!$I$31="",0,COUNTIFS(Itinerary_Tags!$A:$A,$A6,Itinerary_Tags!$B:$B,Filter_Options!$I$31))+IF(Filter_Options!$J$31="",0,COUNTIFS(Itinerary_Tags!$A:$A,$A6,Itinerary_Tags!$B:$B,Filter_Options!$J$31))+IF(Filter_Options!$K$31="",0,COUNTIFS(Itinerary_Tags!$A:$A,$A6,Itinerary_Tags!$B:$B,Filter_Options!$K$31)))>0)) | AG6: =IF($A6="","",--((IF(Filter_Options!$I$32="",0,COUNTIFS(Itinerary_Tags!$A:$A,$A6,Itinerary_Tags!$B:$B,Filter_Options!$I$32))+IF(Filter_Options!$J$32="",0,COUNTIFS(Itinerary_Tags!$A:$A,$A6,Itinerary_Tags!$B:$B,Filter_Options!$J$32))+IF(Filter_Options!$K$32="",0,COUNTIFS(Itinerary_Tags!$A:$A,$A6,Itinerary_Tags!$B:$B,Filter_Options!$K$32)))>0)) | AH6: =IF($A6="","",--((IF(Filter_Options!$I$33="",0,COUNTIFS(Itinerary_Tags!$A:$A,$A6,Itinerary_Tags!$B:$B,Filter_Options!$I$33))+IF(Filter_Options!$J$33="",0,COUNTIFS(Itinerary_Tags!$A:$A,$A6,Itinerary_Tags!$B:$B,Filter_Options!$J$33))+IF(Filter_Options!$K$33="",0,COUNTIFS(Itinerary_Tags!$A:$A,$A6,Itinerary_Tags!$B:$B,Filter_Options!$K$33)))>0)) | AI6: =IF($A6="","",--((IF(Filter_Options!$I$34="",0,COUNTIFS(Itinerary_Tags!$A:$A,$A6,Itinerary_Tags!$B:$B,Filter_Options!$I$34))+IF(Filter_Options!$J$34="",0,COUNTIFS(Itinerary_Tags!$A:$A,$A6,Itinerary_Tags!$B:$B,Filter_Options!$J$34))+IF(Filter_Options!$K$34="",0,COUNTIFS(Itinerary_Tags!$A:$A,$A6,Itinerary_Tags!$B:$B,Filter_Options!$K$34)))>0)) | AJ6: =IF($A6="","",--((IF(Filter_Options!$I$35="",0,COUNTIFS(Itinerary_Tags!$A:$A,$A6,Itinerary_Tags!$B:$B,Filter_Options!$I$35))+IF(Filter_Options!$J$35="",0,COUNTIFS(Itinerary_Tags!$A:$A,$A6,Itinerary_Tags!$B:$B,Filter_Options!$J$35))+IF(Filter_Options!$K$35="",0,COUNTIFS(Itinerary_Tags!$A:$A,$A6,Itinerary_Tags!$B:$B,Filter_Options!$K$35)))>0)) | AK6: =IF($A6="","",--((IF(Filter_Options!$I$36="",0,COUNTIFS(Itinerary_Tags!$A:$A,$A6,Itinerary_Tags!$B:$B,Filter_Options!$I$36))+IF(Filter_Options!$J$36="",0,COUNTIFS(Itinerary_Tags!$A:$A,$A6,Itinerary_Tags!$B:$B,Filter_Options!$J$36))+IF(Filter_Options!$K$36="",0,COUNTIFS(Itinerary_Tags!$A:$A,$A6,Itinerary_Tags!$B:$B,Filter_Options!$K$36)))>0)) | AL6: =IF($A6="","",--((IF(Filter_Options!$I$37="",0,COUNTIFS(Itinerary_Tags!$A:$A,$A6,Itinerary_Tags!$B:$B,Filter_Options!$I$37))+IF(Filter_Options!$J$37="",0,COUNTIFS(Itinerary_Tags!$A:$A,$A6,Itinerary_Tags!$B:$B,Filter_Options!$J$37))+IF(Filter_Options!$K$37="",0,COUNTIFS(Itinerary_Tags!$A:$A,$A6,Itinerary_Tags!$B:$B,Filter_Options!$K$37)))>0))
